Workbook

Sheet NOMINA DE NOVIEMBRE
A1: NÓMINA DE PERSONAL DE NOVIEMBRE 2025
A4: Asociado - Número de Documento | B4: Asociado - Estado | C4: Asociado - Nombre Completo | D4: Asociado - Código de Ficha | E4: Asociado - Sexo | F4: Trabajo - Fecha Ingreso Compañía | G4: Asociado - Fecha de Nacimiento | H4: Asociado - Teléfono Particular | I4: Trabajo - Nombre Área | J4: Trabajo - Nombre Sub-área Asignada(o) | K4: Trabajo - Cargo | L4: Trabajo - Tipo de Contrato | M4: Trabajo - Tipo de Jornada | N4: Trabajo - Sindicato | O4: Trabajo - Jornada Laboral | P4: Trabajo - Horas Semanales | Q4: Trabajo - Fecha Vencimiento Contrato
A5: 16.369.570-7 | B5: Activo | C5: Fuentes Castillo Macarena Alejandra | D5: F1 | E5: F | F5: 45873 | G5: 32003 | H5: 994060922 | I5: F&B | J5: OFICINA DE BANQUETES | K5: COORDINADOR(A) DE BANQUETES | L5: Indefinido | M5: Ordinaria ART 22 | N5: Extensión de Beneficio Sindicato 1 | O5: mensual | P5: 42.5
A6: 23.816.541-5 | B6: Activo | C6: Pecovnik Cortes Igor | D6: F1 | E6: M | F6: 42911 | G6: 26528 | H6: 999368991 | I6: ROOMS | J6: GROOMS | K6: Grooms/Portero/Valet | L6: Indefinido | M6: Ordinaria ART 22 | N6: Sindicato 1 | O6: mensual | P6: 42.5
A7: 19.894.223-5 | B7: Activo | C7: Faundez Vallejos Ailin Cricel | D7: F1 | E7: F | F7: 45740 | G7: 35733 | H7: 966647464 | I7: ADMINISTRACION Y GERENCIA | J7: SEGURIDAD | K7: GUARDIA | L7: Indefinido | M7: Ordinaria ART 22 | N7: Sindicato 1 | O7: mensual | P7: 44
A8: 19.429.624-k | B8: Activo | C8: Pons Valenzuela Fernanda Edith | D8: F1 | E8: F | F8: 45733 | G8: 35314 | H8: 957168583 | I8: F&B | J8: COCINA | K8: COMMIS | L8: Indefinido | M8: Ordinaria ART 22 | N8: Sindicato 1 | O8: mensual | P8: 42.5
A9: 25.399.125-9 | B9: Activo | C9: Seljak Piña Franz Isidro | D9: F1 | E9: F | F9: 45698 | G9: 34083 | H9: 958147239 | I9: F&B | J9: COCINA | K9: CHEF DE PARTIE | L9: Indefinido | M9: Ordinaria ART 22 | N9: Sindicato 1 | O9: mensual | P9: 42.5
A10: 19.837.527-6 | B10: Activo | C10: Troncoso Enriquez Luis David | D10: F1 | E10: M | F10: 45873 | G10: 35732 | H10: 965198972 | I10: ROOMS | J10: GUEST SERVICES AGENT | K10: GUEST SERVICE AGENT | L10: Indefinido | M10: Ordinaria ART 22 | N10: Extensión de Beneficio Sindicato 2 | O10: mensual | P10: 42.5
A11: 10.234.877-k | B11: Activo | C11: Salas Villaceca David Antonio | D11: F1 | E11: M | F11: 38153 | G11: 23601 | H11: 988189560 | I11: ADMINISTRACION Y GERENCIA | J11: CONTRALORIA | K11: CAJERO CENTRAL/COBRADOR | L11: Indefinido | M11: Exenta ART 22 | N11: Extensión de Beneficio Sindicato 1 | O11: mensual | P11: 42.5
A12: 26.610.495-2 | B12: Inactivo | C12: Pierre - Esaie | D12: F-1jul25 | E12: M | F12: 45842 | G12: 34217 | H12: 968759462 | I12: F&B | J12: STEWARD | K12: PLAQUECERO | L12: Plazo fijo | M12: Ordinaria ART 22 | N12: Extensión de Beneficio Sindicato 1 | O12: mensual | P12: 42.5
A13: 17.924.524-8 | B13: Activo | C13: Marinao Cid Gabriel Isaías | D13: F1 | E13: M | F13: 45810 | G13: 33394 | H13: 926220231 | I13: ADMINISTRACION Y GERENCIA | J13: SEGURIDAD | K13: GUARDIA | L13: Indefinido | M13: Ordinaria ART 22 | N13: Sindicato 1 | O13: mensual | P13: 44
A14: 21.286.136-7 | B14: Activo | C14: Fieldhouse Reyes Alonso Emilio | D14: F1 | E14: M | F14: 45864 | G14: 37736 | H14: 965773140 | I14: ROOMS | J14: GUEST SERVICES AGENT | K14: GUEST SERVICE AGENT | L14: Indefinido | M14: Ordinaria ART 22 | N14: Sindicato 1 | O14: mensual | P14: 42.5
A15: 15.381.940-8 | B15: Activo | C15: Mora Gutierrez Rodrigo Alejandro | D15: F1 | E15: M | F15: 45854 | G15: 30236 | H15: 973379381 | I15: F&B | J15: STEWARD | K15: PLAQUECERO | L15: Indefinido | M15: Ordinaria ART 22 | N15: Sindicato 1 | O15: mensual | P15: 42.5
A16: 9.608.528-1 | B16: Activo | C16: Sepulveda Veloso Javier Antonio | D16: F1 | E16: M | F16: 45356 | G16: 23263 | H16: 997339466 | I16: ADMINISTRACION Y GERENCIA | J16: SEGURIDAD | K16: GUARDIA | L16: Indefinido | M16: Ordinaria ART 22 | N16: Sindicato 1 | O16: mensual | P16: 44
... A204: 21.495.104-5 | B204: Activo | C204: Javia Pinto Ignacio Antonio | D204: F-3oct25 | E204: M | F204: 45949 | G204: 38007 | H204: 932115423 | I204: F&B | J204: EL BOHIO | K204: GARZON/CAJERO OUTLETS | L204: Plazo fijo | M204: Ordinaria ART 22 | N204: Extensión de Beneficio Sindicato 2 | O204: mensual | P204: 42.5
A205: 20.960.571-6 | B205: Inactivo | C205: Mora Gonzalez Williams Alberto | D205: F-3oct25 | E205: M | F205: 45949 | G205: 37282 | H205: 990813163 | I205: F&B | J205: EL BOHIO | K205: GARZON/CAJERO OUTLETS | L205: Plazo fijo | M205: Ordinaria ART 22 | O205: mensual | P205: 42.5
A206: 20.049.364-8 | B206: Activo | C206: Cortés Romero Ignacio Javier | D206: F1 | E206: M | F206: 45873 | G206: 36260 | H206: 986115473 | I206: INGENIERIA | J206: INGENIERIA | K206: KEN FIX IT | L206: Indefinido | M206: Ordinaria ART 22 | N206: Extensión de Beneficio Sindicato 2 | O206: mensual | P206: 42.5
A207: 19.634.304-0 | B207: Activo | C207: Saavedra Rivas Víctor Ariel | D207: F1 | E207: M | F207: 45873 | G207: 35570 | H207: 933460928 | I207: INGENIERIA | J207: INGENIERIA | K207: KEN FIX IT | L207: Indefinido | M207: Ordinaria ART 22 | N207: Extensión de Beneficio Sindicato 2 | O207: mensual | P207: 42.5
A208: 17.317.967-7 | B208: Activo | C208: Maldonado Castro Pablo Andrés | D208: F1 | E208: M | F208: 45873 | G208: 33033 | H208: 932683071 | I208: INGENIERIA | J208: INGENIERIA | K208: ENGINEER II | L208: Indefinido | M208: Ordinaria ART 22 | N208: Sindicato 1 | O208: mensual | P208: 42.5
A209: 22.157.857-0 | B209: Activo | C209: Sanchez Diaz Javier Ignacio | D209: F-4sep25 | E209: M | F209: 45925 | G209: 38904 | H209: 920141902 | I209: F&B | J209: COCINA | K209: COMMIS | L209: Plazo fijo | M209: Ordinaria ART 22 | N209: Extensión de Beneficio Sindicato 1 | O209: mensual | P209: 42.5
A210: 19.892.710-4 | B210: Activo | C210: Acevedo Almonte Bernardita Sofía | D210: F1 | E210: F | F210: 45705 | G210: 35978 | H210: 990802454 | I210: VENTAS Y MARKETING | J210: RELACIONES PUBLICAS | K210: COORDINADORA DE MARKETING | L210: Indefinido | M210: Exenta ART 22 | N210: Sindicato 2 | O210: mensual | P210: 44
A211: 10.637.832-0 | B211: Activo | C211: Novoa Reyes Alejandra Elizabeth | D211: F1 | E211: F | F211: 41071 | G211: 27881 | H211: 984395990 | I211: VENTAS Y MARKETING | J211: VENTAS | K211: ACCOUNT MANAGER | L211: Indefinido | M211: Exenta ART 22 | N211: Sindicato 2 | O211: mensual | P211: 42.5
A212: 21.323.547-8 | B212: Inactivo | C212: Molina Pizarro Genesis Alejandra | D212: F-2oct25 | E212: F | F212: 45938 | G212: 37780 | H212: 976538500 | I212: F&B | J212: ROOM SERVICE | K212: GARZON/CAJERO OUTLETS | L212: Plazo fijo | M212: Ordinaria ART 22 | N212: Extensión de Beneficio Sindicato 1 | O212: mensual | P212: 42.5
A213: 20.590.424-7 | B213: Inactivo | C213: Olivares Contreras Ruben Eliseo | D213: F-2oct25 | E213: M | F213: 45938 | G213: 36788 | H213: 971245851 | I213: F&B | J213: CID | K213: GARZON/CAJERO OUTLETS | L213: Plazo fijo | M213: Ordinaria ART 22 | N213: Extensión de Beneficio Sindicato 1 | O213: mensual | P213: 42.5
A214: 20.054.413-7 | B214: Activo | C214: Lecaros Tapia Francisco Javier | D214: F-1oct25 | E214: M | F214: 45937 | G214: 36179 | H214: 964463846 | I214: F&B | J214: LOBBY BAR | K214: BARTENDER | L214: Plazo fijo | M214: Ordinaria ART 22 | N214: Extensión de Beneficio Sindicato 1 | O214: mensual | P214: 42.5
A215: 20.153.031-8 | B215: Activo | C215: Gonzalez Marileo Francisco Andres | D215: F-2oct25 | E215: M | F215: 45937 | G215: 36607 | H215: 989470565 | I215: F&B | J215: LOBBY BAR | K215: BARTENDER | L215: Plazo fijo | M215: Ordinaria ART 22 | N215: Extensión de Beneficio Sindicato 1 | O215: mensual | P215: 42.5
A216: 13.696.002-4 | B216: Activo | C216: Quintana Contreras Carolina Alejandra | D216: F1 | E216: F | F216: 43640 | G216: 29116 | H216: 964821590 | I216: VENTAS Y MARKETING | J216: VENTAS | K216: ACCOUNT MANAGER | L216: Indefinido | M216: Exenta ART 22 | N216: Sindicato 2 | O216: mensual | P216: 42.5
A217: 25.724.970-0 | B217: Activo | C217: Araujo Moya Naibel Del Valle | D217: F1 | E217: F | F217: 45936 | G217: 31847 | H217: 971772773 | I217: MEMO | J217: PALAFITO | K217: CHEF ENCARGADO DE PALAFITO | L217: Indefinido | M217: Ordinaria ART 22 | N217: Extensión de Beneficio Sindicato 1 | O217: mensual | P217: 42.5
... A222: 19.994.792-3 | B222: Inactivo | C222: Garay Rojas Diego Ignacio | D222: F-3oct25 | E222: M | F222: 45943 | G222: 36043 | H222: 998816408 | I222: ROOMS | J222: PUBLIC AREAS | K222: ASEADOR (A) /OPERARIO DE LAVANDERIA | L222: Plazo fijo | M222: Ordinaria ART 22 | N222: Extensión de Beneficio Sindicato 2 | O222: mensual | P222: 42.5
A223: 8.952.862-3 | B223: Activo | C223: Dehnhardt Ormeño David Alejandro | D223: F1 | E223: M | F223: 45026 | G223: 27300 | H223: 977066442 | I223: F&B ADM | J223: F&B ADMINISTRATION | K223: DIRECTOR FOOD & BEVERAGE | L223: Indefinido | M223: Exenta ART 22 | O223: mensual | P223: 42.5
A224: 21.774.085-1 | B224: Inactivo | C224: Jamed Cabezas Amanda Francisca | D224: F-1oct25 | E224: F | F224: 45934 | G224: 38396 | H224: 971085903 | I224: ROOMS | J224: GUEST SERVICES AGENT | K224: GUEST SERVICE AGENT | L224: Plazo fijo | M224: Ordinaria ART 22 | N224: Extensión de Beneficio Sindicato 2 | O224: mensual | P224: 42.5
A225: 22.386.150-4 | B225: Inactivo | C225: Ravanal Orellana Angel Del Piero | D225: F-4oct25 | E225: M | F225: 45950 | G225: 39191 | H225: 974681406 | I225: ROOMS | J225: AMA DE LLAVES | K225: Lencera (o) | L225: Plazo fijo | M225: Ordinaria ART 22 | N225: Extensión de Beneficio Sindicato 2 | O225: diaria | P225: 42.5
A226: 18.443.563-2 | B226: Activo | C226: Vidal Cerecer Pablo Antonio | D226: F-4oct25 | E226: M | F226: 45950 | G226: 34156 | H226: 982577080 | I226: ADMINISTRACION Y GERENCIA | J226: PREVENCION DE RIESGOS | K226: PREVENCIONISTA DE RIESGOS | L226: Plazo fijo | M226: Ordinaria ART 22 | N226: Extensión de Beneficio Sindicato 1 | O226: mensual | P226: 42.5
A227: 9.715.305-1 | B227: Activo | C227: Troncoso Latorre Maybett Del Carmen | D227: F-4oct25 | E227: F | F227: 45952 | G227: 25776 | H227: 942060223 | I227: ROOMS | J227: PUBLIC AREAS | K227: ASEADOR (A) /OPERARIO DE LAVANDERIA | L227: Plazo fijo | M227: Ordinaria ART 22 | N227: Extensión de Beneficio Sindicato 2 | O227: mensual | P227: 42.5
A228: 19.824.335-3 | B228: Activo | C228: Mardones Melo Esteban Elias | D228: F-4oct25 | E228: M | F228: 45952 | G228: 36036 | H228: 932964723 | I228: F&B | J228: ROOM SERVICE | K228: GARZON/CAJERO OUTLETS | L228: Plazo fijo | M228: Ordinaria ART 22 | N228: Extensión de Beneficio Sindicato 1 | O228: mensual | P228: 42.5
A229: 21.980.969-7 | B229: Activo | C229: Contreras Gallardo Martin Ricardo | D229: F-4oct25 | E229: M | F229: 45951 | G229: 38673 | H229: 942824175 | I229: MEMO | J229: PALAFITO | K229: COMMIS | L229: Plazo fijo | M229: Ordinaria ART 22 | N229: Extensión de Beneficio Sindicato 2 | O229: mensual | P229: 42.5
A230: 21.090.054-3 | B230: Inactivo | C230: Inostroza Vidal Cristóbal Francisco | D230: F-4oct25 | E230: M | F230: 45952 | G230: 37423 | H230: 930937041 | I230: F&B | J230: BANQUETES SERVICE | K230: ASEADOR/GUARDARROPIA | L230: Plazo fijo | M230: Ordinaria ART 22 | N230: Extensión de Beneficio Sindicato 2 | O230: mensual | P230: 42.5
A231: 19.881.327-3 | B231: Inactivo | C231: Mendoza Gonzalez Edy Santiago | D231: F-4oct25 | E231: M | F231: 45951 | G231: 35927 | H231: 949393956 | I231: F&B | J231: BANQUETES SERVICE | K231: GARZON/SALONERO BANQUETES | L231: Plazo fijo | M231: Ordinaria ART 22 | N231: Extensión de Beneficio Sindicato 1 | O231: mensual | P231: 42.5
A232: 21.471.617-8 | B232: Activo | C232: Sotelo Rosales Samuel Andrés | D232: F-4oct25 | E232: M | F232: 45953 | G232: 37968 | H232: 971912943 | I232: ROOMS | J232: PUBLIC AREAS | K232: ASEADOR (A) /OPERARIO DE LAVANDERIA | L232: Plazo fijo | M232: Ordinaria ART 22 | N232: Extensión de Beneficio Sindicato 2 | O232: mensual | P232: 42.5
A233: 20.703.802-4 | B233: Activo | C233: Díaz Gatica Diego Alonso | D233: F-4oct25 | E233: M | F233: 45953 | G233: 36913 | H233: 995326767 | I233: ROOMS | J233: AMA DE LLAVES | K233: Operario Mini Bar | L233: Plazo fijo | M233: Ordinaria ART 22 | N233: Extensión de Beneficio Sindicato 1 | O233: mensual | P233: 42.5
...

Sheet BAJAS NOVIEMBRE
A1: BAJAS DE NOVIEMBRE 2025
A4: Asociado - Número de Documento | B4: ESTADO | C4: Asociado - Estado | D4: Asociado - Código de Ficha | E4: Asociado - Nombre Completo | F4: Trabajo - Nombre Área Asignada(o) | G4: Trabajo - Nombre Sub-área Asignada(o) | H4: Trabajo - Cargo | I4: Trabajo - Fecha Ingreso Compañía | J4: Trabajo - Fecha Vencimiento Contrato | K4: Trabajo - Tipo de Contrato | L4: Trabajo - Tipo de Jornada | M4: Trabajo - Jornada Laboral | N4: Asociado - Forma de Pago | O4: Asociado - Banco | P4: Asociado - Tipo de Cuenta | Q4: Asociado - Número de Cuenta | R4: Trabajo - Fecha Término Trabajo | S4: Trabajo - Razón de Término | T4: Asociado - Fecha Pago de Finiquito | U4: Campos Personalizados de Asociado - Estado Finiquito | V4: Campos Personalizados de Asociado - Estado Finiquito | W4: Campos Personalizados de Asociado - Forma Pago Finiquito | X4: Campos Personalizados de Asociado - Fecha de Pago
A5: 24.753.417-2 | B5: =VLOOKUP(A5,'NOMINA DICIEMBRE'!A:Q,3,0) -> #N/A | C5: Inactivo | D5: F-3sep25 | E5: Velazquez Maria Eugenia | F5: =VLOOKUP(A5,'NOMINA OCTUBRE'!A:Q,9,0) -> MEMO | G5: =VLOOKUP(A5,'NOMINA OCTUBRE'!A:Q,10,0) -> PALAFITO | H5: =VLOOKUP(A5,'NOMINA OCTUBRE'!A:Q,11,0) -> AYUDANTE DE COCINA / PLAQUECERO | I5: 45915 | J5: 45973 | K5: Plazo fijo | L5: Ordinaria ART 22 | M5: mensual | N5: Transferencia Bancaria | O5: Santander | P5: Ahorro | Q5: 80626053 | R5: 45973 | S5: vencimiento_plazo | T5: 45975
A6: 20.388.609-8 | B6: =VLOOKUP(A6,'NOMINA DICIEMBRE'!A:Q,3,0) -> #N/A | C6: Inactivo | D6: F-3oct25 | E6: González Vásquez Xavier Alexander Ghary | F6: =VLOOKUP(A6,'NOMINA OCTUBRE'!A:Q,9,0) -> MEMO | G6: =VLOOKUP(A6,'NOMINA OCTUBRE'!A:Q,10,0) -> PALAFITO | H6: =VLOOKUP(A6,'NOMINA OCTUBRE'!A:Q,11,0) -> COMMIS | I6: 45948 | J6: 45985 | K6: Plazo fijo | L6: Ordinaria ART 22 | M6: mensual | N6: Transferencia Bancaria | O6: Banco Estado | P6: Vista | Q6: 20388609 | R6: 45974 | S6: renuncia | T6: 45982
A7: 18.936.748-1 | B7: =VLOOKUP(A7,'NOMINA DICIEMBRE'!A:Q,3,0) -> #N/A | C7: Inactivo | D7: F1 | E7: Acuña Alarcon Jose Pablo | F7: =VLOOKUP(A7,'NOMINA OCTUBRE'!A:Q,9,0) -> F&B | G7: =VLOOKUP(A7,'NOMINA OCTUBRE'!A:Q,10,0) -> OFICINA DE BANQUETES | H7: =VLOOKUP(A7,'NOMINA OCTUBRE'!A:Q,11,0) -> COORDINADOR(A) DE BANQUETES | I7: 43212 | K7: Indefinido | L7: Ordinaria ART 22 | M7: mensual | N7: Transferencia Bancaria | O7: Banco de Chile | P7: Corriente | Q7: 3631007608 | R7: 45971 | S7: renuncia | T7: 45974
A8: 19.994.792-3 | B8: =VLOOKUP(A8,'NOMINA DICIEMBRE'!A:Q,3,0) -> #N/A | C8: Inactivo | D8: F-3oct25 | E8: Garay Rojas Diego Ignacio | F8: =VLOOKUP(A8,'NOMINA OCTUBRE'!A:Q,9,0) -> ROOMS | G8: =VLOOKUP(A8,'NOMINA OCTUBRE'!A:Q,10,0) -> PUBLIC AREAS | H8: =VLOOKUP(A8,'NOMINA OCTUBRE'!A:Q,11,0) -> ASEADOR (A) /OPERARIO DE LAVANDERIA | I8: 45943 | J8: 45971 | K8: Plazo fijo | L8: Ordinaria ART 22 | M8: mensual | N8: Transferencia Bancaria | O8: Falabella | P8: Corriente | Q8: 19840072021 | R8: 45971 | S8: vencimiento_plazo | T8: 45975
A9: 19.664.249-8 | B9: =VLOOKUP(A9,'NOMINA DICIEMBRE'!A:Q,3,0) -> #N/A | C9: Inactivo | D9: F-4oct25 | E9: Martinez Beltran Victor Manuel | F9: =VLOOKUP(A9,'NOMINA OCTUBRE'!A:Q,9,0) -> ROOMS | G9: =VLOOKUP(A9,'NOMINA OCTUBRE'!A:Q,10,0) -> GUEST SERVICES AGENT | H9: =VLOOKUP(A9,'NOMINA OCTUBRE'!A:Q,11,0) -> GUEST SERVICE AGENT | I9: 45953 | J9: 45978 | K9: Plazo fijo | L9: Ordinaria ART 22 | M9: mensual | N9: Transferencia Bancaria | O9: Banco Estado | P9: Vista | Q9: 19664249 | R9: 45978 | S9: vencimiento_plazo | T9: 45982
A10: 24.210.636-9 | B10: =VLOOKUP(A10,'NOMINA DICIEMBRE'!A:Q,3,0) -> #N/A | C10: Inactivo | D10: F-4oct25 | E10: Ramos De La Cruz Judelka | F10: =VLOOKUP(A10,'NOMINA OCTUBRE'!A:Q,9,0) -> F&B | G10: =VLOOKUP(A10,'NOMINA OCTUBRE'!A:Q,10,0) -> LOBBY BAR | H10: =VLOOKUP(A10,'NOMINA OCTUBRE'!A:Q,11,0) -> GARZON/CAJERO OUTLETS | I10: 45953 | J10: 45985 | K10: Plazo fijo | L10: Ordinaria ART 22 | M10: mensual | N10: Transferencia Bancaria | O10: Ripley | P10: Corriente | Q10: 4012291559 | R10: 45985 | S10: vencimiento_plazo | T10: 45988
A11: 12.883.097-9 | B11: =VLOOKUP(A11,'NOMINA DICIEMBRE'!A:Q,3,0) -> #N/A | C11: Inactivo | D11: F1 | E11: Iriondo Nicoletti Maria Begoña | F11: =VLOOKUP(A11,'NOMINA OCTUBRE'!A:Q,9,0) -> VENTAS Y MARKETING | G11: =VLOOKUP(A11,'NOMINA OCTUBRE'!A:Q,10,0) -> VENTAS | H11: =VLOOKUP(A11,'NOMINA OCTUBRE'!A:Q,11,0) -> DIRECTOR DE VENTAS Y MARKETING | I11: 40406 | K11: Indefinido | L11: Exenta ART 22 | M11: mensual | N11: Transferencia Bancaria | O11: Scotiabank | P11: Corriente | Q11: 790100048036 | R11: 45982 | S11: necesidades_empresa | T11: 45988
A12: 22.458.381-8 | B12: =VLOOKUP(A12,'NOMINA DICIEMBRE'!A:Q,3,0) -> #N/A | C12: Inactivo | D12: F-1nov25 | E12: Ibañez Huaman Nalleli Brillid | F12: =VLOOKUP(A12,'NOMINA OCTUBRE'!A:Q,9,0) -> ROOMS | G12: =VLOOKUP(A12,'NOMINA OCTUBRE'!A:Q,10,0) -> GROOMS | H12: =VLOOKUP(A12,'NOMINA OCTUBRE'!A:Q,11,0) -> PORTERO/GROOM | I12: 45962 | J12: 45984 | K12: Plazo fijo | L12: Ordinaria ART 22 | M12: diaria | N12: Transferencia Bancaria | O12: Banco Estado | P12: Vista | Q12: 22458381 | R12: 45984 | S12: vencimiento_plazo | T12: 45988
A13: 19.646.384-4 | B13: =VLOOKUP(A13,'NOMINA DICIEMBRE'!A:Q,3,0) -> #N/A | C13: Inactivo | D13: F-2nov25 | E13: Venegas Yáñez Michelle Francisca | F13: F&B | G13: COCINA | H13: COMMIS | I13: 45971 | J13: 45994 | K13: Plazo fijo | L13: Ordinaria ART 22 | M13: mensual | N13: Transferencia Bancaria | O13: Falabella | P13: Corriente | Q13: 15840443994 | R13: 45980 | S13: renuncia | T13: 45982

Sheet ALTAS NOVIEMBRE
A1: ALTAS DE NOVIEMBRE 2025
B3: =VLOOKUP(A3,'NOMINA OCTUBRE'!A:P,3,0) -> #N/A
A4: Asociado - Número de Documento | B4: ESTADO | C4: Asociado - Nombre Completo | D4: Asociado - Código de Ficha | E4: Asociado - Sexo | F4: Trabajo - Fecha Ingreso Compañía | G4: Asociado - Fecha de Nacimiento | H4: Asociado - Teléfono Particular | I4: Trabajo - Nombre Área | J4: Trabajo - Nombre Sub-área Asignada(o) | K4: Trabajo - Cargo | L4: Trabajo - Tipo de Contrato | M4: Trabajo - Tipo de Jornada | N4: Trabajo - Sindicato | O4: Trabajo - Jornada Laboral | P4: Trabajo - Horas Semanales | Q4: Trabajo - Fecha Vencimiento Contrato
A5: 21.392.465-6 | B5: =VLOOKUP(A5,'NOMINA OCTUBRE'!A:P,3,0) -> #N/A | C5: Moreno Rojas Genesis Fernanda | D5: F-1nov25 | E5: F | F5: 45964 | G5: 37879 | H5: 946962558 | I5: F&B | J5: COCINA | K5: COMMIS | L5: Plazo fijo | M5: Ordinaria ART 22 | N5: Extensión de Beneficio Sindicato 2 | O5: mensual | P5: 42.5 | Q5: 45992
A6: 21.727.260-2 | B6: =VLOOKUP(A6,'NOMINA OCTUBRE'!A:P,3,0) -> #N/A | C6: Saldívar Pino Carolina Andrea | D6: F-1nov25 | E6: F | F6: 45964 | G6: 38335 | H6: 931275924 | I6: F&B | J6: COCINA | K6: COMMIS | L6: Plazo fijo | M6: Ordinaria ART 22 | N6: Extensión de Beneficio Sindicato 2 | O6: mensual | P6: 42.5 | Q6: 45992
A7: 20.825.173-2 | B7: =VLOOKUP(A7,'NOMINA OCTUBRE'!A:P,3,0) -> #N/A | C7: Adonis Lopez Chriss Ralfh | D7: F-2nov25 | E7: M | F7: 45971 | G7: 37101 | H7: 998715872 | I7: F&B | J7: LOBBY BAR | K7: GARZON/CAJERO OUTLETS | L7: Plazo fijo | M7: Ordinaria ART 22 | N7: Extensión de Beneficio Sindicato 1 | O7: mensual | P7: 42.5 | Q7: 46034
A8: 21.262.615-5 | B8: =VLOOKUP(A8,'NOMINA OCTUBRE'!A:P,3,0) -> #N/A | C8: Vergara Varas Gabriel Ignacio | D8: F-2nov25 | E8: M | F8: 45971 | G8: 37702 | H8: 933903480 | I8: F&B | J8: CID | K8: GARZON/CAJERO OUTLETS | L8: Plazo fijo | M8: Ordinaria ART 22 | N8: Extensión de Beneficio Sindicato 1 | O8: mensual | P8: 42.5 | Q8: 46027
A9: 20.450.016-9 | B9: =VLOOKUP(A9,'NOMINA OCTUBRE'!A:P,3,0) -> #N/A | C9: Álvarez Álvarez Carolain Belén | D9: F-2nov25 | E9: F | F9: 45971 | G9: 36755 | H9: 976846086 | I9: F&B | J9: COCINA | K9: COMMIS | L9: Plazo fijo | M9: Parcial ART 40 BIS | N9: Extensión de Beneficio Sindicato 2 | O9: mensual | P9: 42.5 | Q9: 45994
A10: 19.646.384-4 | B10: =VLOOKUP(A10,'NOMINA OCTUBRE'!A:P,3,0) -> #N/A | C10: Venegas Yáñez Michelle Francisca | D10: F-2nov25 | E10: F | F10: 45971 | G10: 35515 | H10: 975561071 | I10: F&B | J10: COCINA | K10: COMMIS | L10: Plazo fijo | M10: Ordinaria ART 22 | N10: Extensión de Beneficio Sindicato 1 | O10: mensual | P10: 42.5 | Q10: 45994
A11: 21.054.151-9 | B11: =VLOOKUP(A11,'NOMINA OCTUBRE'!A:P,3,0) -> #N/A | C11: Alvial Poza Benjamín Enoc | D11: F-2nov25 | E11: M | F11: 45971 | G11: 37543 | H11: 940540494 | I11: F&B | J11: COCINA | K11: COMMIS | L11: Plazo fijo | M11: Ordinaria ART 22 | N11: Extensión de Beneficio Sindicato 1 | O11: mensual | P11: 42.5 | Q11: 45994
A12: 25.647.366-6 | B12: =VLOOKUP(A12,'NOMINA OCTUBRE'!A:P,3,0) -> #N/A | C12: Reyes Montenegro Jose Javier | D12: F-2nov25 | E12: M | F12: 45971 | G12: 32561 | H12: 987210254 | I12: F&B | J12: OFICINA DE BANQUETES | K12: COORDINADOR(A) DE BANQUETES | L12: Plazo fijo | M12: Ordinaria ART 22 | N12: Extensión de Beneficio Sindicato 1 | O12: mensual | P12: 42.5 | Q12: 46001
A13: 27.395.783-9 | B13: =VLOOKUP(A13,'NOMINA OCTUBRE'!A:P,3,0) -> #N/A | C13: Lozano Peñaloza Breitner | D13: F-2nov25 | E13: M | F13: 45971 | G13: 34972 | H13: 979742233 | I13: F&B | J13: LOBBY BAR | K13: BARTENDER | L13: Plazo fijo | M13: Ordinaria ART 22 | N13: Extensión de Beneficio Sindicato 2 | O13: mensual | P13: 42.5 | Q13: 45994
A14: 18.539.959-1 | B14: =VLOOKUP(A14,'NOMINA OCTUBRE'!A:P,3,0) -> #N/A | C14: Rojas Jimenez Isidora Nicole | D14: F-2nov25 | E14: F | F14: 45971 | G14: 34164 | H14: 957651598 | I14: F&B | J14: LOBBY BAR | K14: BARTENDER | L14: Plazo fijo | M14: Ordinaria ART 22 | N14: Extensión de Beneficio Sindicato 2 | O14: mensual | P14: 42.5 | Q14: 45994
A15: 19.515.921-1 | B15: =VLOOKUP(A15,'NOMINA OCTUBRE'!A:P,3,0) -> #N/A | C15: Valencia Cárdenas Javier Ignacio | D15: F-2nov25 | E15: M | F15: 45971 | G15: 35345 | H15: 921679075 | I15: F&B | J15: LOBBY BAR | K15: BARTENDER | L15: Plazo fijo | M15: Ordinaria ART 22 | N15: Extensión de Beneficio Sindicato 1 | O15: mensual | P15: 42.5 | Q15: 45994
A16: 20.053.329-1 | B16: =VLOOKUP(A16,'NOMINA OCTUBRE'!A:P,3,0) -> #N/A | C16: Riveros Echeverría Catalina Valentina | D16: F-2nov25 | E16: F | F16: 45971 | G16: 36147 | H16: 955159745 | I16: F&B | J16: OFICINA DE BANQUETES | K16: Asistente de Eventos | L16: Plazo fijo | M16: Ordinaria ART 22 | N16: Extensión de Beneficio Sindicato 1 | O16: mensual | P16: 42.5 | Q16: 46001
A17: 11.166.190-1 | B17: =VLOOKUP(A17,'NOMINA OCTUBRE'!A:P,3,0) -> #N/A | C17: Artigas Espejo Francis Myriam | D17: F-4nov25 | E17: F | F17: 45985 | G17: 24510 | H17: 931973696 | I17: ROOMS | J17: AMA DE LLAVES | K17: MUCAMA (O) /ASEADOR (A) /LENCERA (O) | L17: Plazo fijo | M17: Ordinaria ART 22 | N17: Extensión de Beneficio Sindicato 1 | O17: mensual | P17: 42.5 | Q17: 46015

Sheet NOMINA DICIEMBRE
A1: PEGAR REPORTE " DAILY REPORTE DE BUK " DEL MES VIGENTE
A2: MOVER LA COLUMNA DE NUMERO DE DOCUMENTO AL INICIO
A3: ELIMINAR COLUMNA SUELDO BASE
A4: ELIMINAR COLUMNA Haberes No Imponibles - Movilización
A5: ELIMINAR COLUMNA CENTRO COSTOS Y ADICIONALES
A7: Asociado - Número de Documento | B7: Asociado - Estado | C7: Asociado - Nombre Completo | D7: Asociado - Código de Ficha | E7: Asociado - Sexo | F7: Trabajo - Fecha Ingreso Compañía | G7: Asociado - Fecha de Nacimiento | H7: Asociado - Teléfono Particular | I7: Trabajo - Nombre Área | J7: Trabajo - Nombre Sub-área Asignada(o) | K7: Trabajo - Cargo | L7: Trabajo - Tipo de Contrato | M7: Trabajo - Tipo de Jornada | N7: Trabajo - Sindicato | O7: Trabajo - Jornada Laboral | P7: Trabajo - Horas Semanales | Q7: Trabajo - Fecha Vencimiento Contrato
A8: 23.816.541-5 | B8: Activo | C8: Pecovnik Cortes Igor | D8: F1 | E8: M | F8: 42911 | G8: 26528 | H8: 999368991 | I8: ROOMS | J8: GROOMS | K8: Grooms/Portero/Valet | L8: Indefinido | M8: Ordinaria ART 22 | N8: Sindicato 1 | O8: mensual | P8: 42.5
A9: 19.894.223-5 | B9: Activo | C9: Faundez Vallejos Ailin Cricel | D9: F1 | E9: F | F9: 45740 | G9: 35733 | H9: 966647464 | I9: ADMINISTRACION Y GERENCIA | J9: SEGURIDAD | K9: GUARDIA | L9: Indefinido | M9: Ordinaria ART 22 | N9: Sindicato 1 | O9: mensual | P9: 44
A10: 19.429.624-k | B10: Activo | C10: Pons Valenzuela Fernanda Edith | D10: F1 | E10: F | F10: 45733 | G10: 35314 | H10: 957168583 | I10: F&B | J10: COCINA | K10: COMMIS | L10: Indefinido | M10: Ordinaria ART 22 | N10: Sindicato 1 | O10: mensual | P10: 42.5
A11: 25.399.125-9 | B11: Activo | C11: Seljak Piña Franz Isidro | D11: F1 | E11: F | F11: 45698 | G11: 34083 | H11: 958147239 | I11: F&B | J11: COCINA | K11: CHEF DE PARTIE | L11: Indefinido | M11: Ordinaria ART 22 | N11: Sindicato 1 | O11: mensual | P11: 42.5
A12: 19.837.527-6 | B12: Activo | C12: Troncoso Enriquez Luis David | D12: F1 | E12: M | F12: 45873 | G12: 35732 | H12: 965198972 | I12: ROOMS | J12: GUEST SERVICES AGENT | K12: GUEST SERVICE AGENT | L12: Indefinido | M12: Ordinaria ART 22 | N12: Extensión de Beneficio Sindicato 2 | O12: mensual | P12: 42.5
A13: 10.234.877-k | B13: Activo | C13: Salas Villaceca David Antonio | D13: F1 | E13: M | F13: 38153 | G13: 23601 | H13: 988189560 | I13: ADMINISTRACION Y GERENCIA | J13: CONTRALORIA | K13: CAJERO CENTRAL/COBRADOR | L13: Indefinido | M13: Exenta ART 22 | N13: Extensión de Beneficio Sindicato 1 | O13: mensual | P13: 42.5
A14: 17.924.524-8 | B14: Activo | C14: Marinao Cid Gabriel Isaías | D14: F1 | E14: M | F14: 45810 | G14: 33394 | H14: 926220231 | I14: ADMINISTRACION Y GERENCIA | J14: SEGURIDAD | K14: GUARDIA | L14: Indefinido | M14: Ordinaria ART 22 | N14: Sindicato 1 | O14: mensual | P14: 44
A15: 21.286.136-7 | B15: Activo | C15: Fieldhouse Reyes Alonso Emilio | D15: F1 | E15: M | F15: 45864 | G15: 37736 | H15: 965773140 | I15: ROOMS | J15: GUEST SERVICES AGENT | K15: GUEST SERVICE AGENT | L15: Indefinido | M15: Ordinaria ART 22 | N15: Sindicato 1 | O15: mensual | P15: 42.5
A16: 9.608.528-1 | B16: Activo | C16: Sepulveda Veloso Javier Antonio | D16: F1 | E16: M | F16: 45356 | G16: 23263 | H16: 997339466 | I16: ADMINISTRACION Y GERENCIA | J16: SEGURIDAD | K16: GUARDIA | L16: Indefinido | M16: Ordinaria ART 22 | N16: Sindicato 1 | O16: mensual | P16: 44
A17: 11.666.268-k | B17: Activo | C17: Zambrano Mandiola Bernarda Julia | D17: F1 | E17: F | F17: 45821 | G17: 25728 | H17: 939582128 | I17: ROOMS | J17: AMA DE LLAVES | K17: MUCAMA (O) /ASEADOR (A) /LENCERA (O) | L17: Indefinido | M17: Ordinaria ART 22 | N17: Sindicato 2 | O17: mensual | P17: 42.5
A18: 26.432.526-9 | B18: Activo | C18: Shephard Matos Francia Elizabeth | D18: F1 | E18: F | F18: 45815 | G18: 29055 | H18: 950352960 | I18: ROOMS | J18: AMA DE LLAVES | K18: MUCAMA (O) /ASEADOR (A) /LENCERA (O) | L18: Indefinido | M18: Ordinaria ART 22 | N18: Sindicato 2 | O18: mensual | P18: 42.5
A19: 20.673.002-1 | B19: Activo | C19: Roco Aguirre Enzo Valentino | D19: F1 | E19: M | F19: 45642 | G19: 36998 | H19: 922004346 | I19: ROOMS | J19: GUEST SERVICES AGENT | K19: GUEST SERVICE AGENT | L19: Indefinido | M19: Ordinaria ART 22 | N19: Sindicato 1 | O19: mensual | P19: 42.5
... A23: 16.373.482-6 | B23: Activo | C23: Fernández Gómez José Luis | D23: F1 | E23: M | F23: 45810 | G23: 31549 | H23: 967268112 | I23: ADMINISTRACION Y GERENCIA | J23: STORE COST CONTROL | K23: ENCARGADO DE BODEGA | L23: Indefinido | M23: Ordinaria ART 22 | N23: Sindicato 1 | O23: mensual | P23: 42.5
A24: 13.255.671-7 | B24: Activo | C24: Gómez Zenteno Rafael Andrés | D24: F-1ago25 | E24: M | F24: 45873 | G24: 28259 | H24: 951557885 | I24: VENTAS Y MARKETING | J24: DIPLOMATS | K24: Ejecutivo/a Diplomats | L24: Plazo fijo | M24: Ordinaria ART 22 | N24: Extensión de Beneficio Sindicato 2 | O24: mensual | P24: 42.5 | Q24: 46026
A25: 14.131.634-6 | B25: Activo | C25: Menchaca Fernández María Constanza | D25: F1 | E25: F | F25: 45803 | G25: 29666 | H25: 994358167 | I25: VENTAS Y MARKETING | J25: VENTAS | K25: EJECUTIVA DE VENTAS DE NUEVOS NEGOCIOS | L25: Indefinido | M25: Exenta ART 22 | N25: Extensión de Beneficio Sindicato 2 | O25: mensual | P25: 44
A26: 20.108.477-6 | B26: Activo | C26: Moreno Laso Vicente Daniel | D26: F1 | E26: M | F26: 45810 | G26: 36248 | H26: 942775139 | I26: ADMINISTRACION Y GERENCIA | J26: CONTRALORIA | K26: Auxiliar de Créditos | L26: Indefinido | M26: Ordinaria ART 22 | N26: Extensión de Beneficio Sindicato 2 | O26: mensual | P26: 42.5
A27: 20.761.204-9 | B27: Activo | C27: Parra Quezada Giulliana Stephani | D27: F1 | E27: F | F27: 45810 | G27: 37023 | H27: 939039706 | I27: ADMINISTRACION Y GERENCIA | J27: CONTRALORIA | K27: Auxiliar de Créditos | L27: Indefinido | M27: Ordinaria ART 22 | N27: Extensión de Beneficio Sindicato 1 | O27: mensual | P27: 42.5
A28: 10.807.412-4 | B28: Activo | C28: Sáez Barrios Jean Eric | D28: F1 | E28: M | F28: 45810 | G28: 28931 | H28: 968141966 | I28: VENTAS Y MARKETING | J28: VENTAS | K28: Ejecutivo de Cuentas Tour & Travel | L28: Indefinido | M28: Exenta ART 22 | N28: Extensión de Beneficio Sindicato 1 | O28: mensual | P28: 44
A29: 27.917.972-2 | B29: Activo | C29: Fernandez Mambuscay Julian Estiben | D29: F1 | E29: M | F29: 44972 | G29: 37092 | H29: 993010961 | I29: F&B | J29: STEWARD | K29: SUPERVISOR STEWARD | L29: Indefinido | M29: Ordinaria ART 22 | N29: Sindicato 1 | O29: mensual | P29: 42.5
A30: 26.409.239-6 | B30: Activo | C30: Anzola Villalon Juan Carlos | D30: F1 | E30: M | F30: 43608 | G30: 27715 | H30: 994905005 | I30: F&B | J30: STEWARD | K30: SUPERVISOR STEWARD | L30: Indefinido | M30: Ordinaria ART 22 | N30: Sindicato 1 | O30: mensual | P30: 42.5
A31: 28.184.786-4 | B31: Activo | C31: Feltran Loubens | D31: F1 | E31: M | F31: 45298 | G31: 34281 | H31: 936263836 | I31: F&B | J31: STEWARD | K31: SUPERVISOR STEWARD | L31: Indefinido | M31: Ordinaria ART 22 | N31: Sindicato 1 | O31: mensual | P31: 42.5
A32: 13.679.411-6 | B32: Activo | C32: Irarrazabal Contreras Sabrina Gisella | D32: F1 | E32: F | F32: 45266 | G32: 28879 | H32: 983037941 | I32: F&B | J32: CID | K32: BARTENDER | L32: Indefinido | M32: Ordinaria ART 22 | N32: Sindicato 1 | O32: mensual | P32: 42.5
A33: 17.217.358-6 | B33: Activo | C33: Borquez Venegas Mario Alejandro | D33: F1 | E33: M | F33: 45278 | G33: 32862 | H33: 56983577085 | I33: F&B | J33: LOBBY BAR | K33: BARTENDER | L33: Indefinido | M33: Ordinaria ART 22 | N33: Sindicato 1 | O33: mensual | P33: 42.5
A34: 19.292.167-8 | B34: Activo | C34: Martinez Pérez Francisca Andrea | D34: F1 | E34: F | F34: 45670 | G34: 35142 | H34: 936559107 | I34: F&B | J34: LOBBY BAR | K34: BARTENDER | L34: Indefinido | M34: Ordinaria ART 22 | N34: Sindicato 1 | O34: mensual | P34: 42.5
A35: 19.736.484-k | B35: Activo | C35: Arevalo Díaz Ignacio Alfonso | D35: F1 | E35: M | F35: 45666 | G35: 35747 | H35: 985013018 | I35: F&B | J35: LOBBY BAR | K35: BARTENDER | L35: Indefinido | M35: Ordinaria ART 22 | N35: Sindicato 1 | O35: mensual | P35: 42.5
A36: 20.059.173-9 | B36: Activo | C36: Medina Pino Amapola Belen | D36: F1 | E36: F | F36: 45683 | G36: 36273 | H36: 999858027 | I36: F&B | J36: LOBBY BAR | K36: BARTENDER | L36: Indefinido | M36: Ordinaria ART 22 | N36: Sindicato 1 | O36: mensual | P36: 42.5
... A56: 18.337.130-4 | B56: Activo | C56: Bernal Pizarro Diego Antonio | D56: F1 | E56: M | F56: 41649 | G56: 33919 | H56: 987452858 | I56: ADMINISTRACION Y GERENCIA | J56: STORE COST CONTROL | K56: RECEPCIONISTA DE MERCADERIA | L56: Indefinido | M56: Ordinaria ART 22 | N56: Sindicato 2 | O56: mensual | P56: 42.5
A57: 26.018.535-7 | B57: Activo | C57: Josema - Bettyna | D57: F-3ago25 | E57: F | F57: 45890 | G57: 37362 | H57: 928848614 | I57: F&B | J57: STEWARD | K57: PLAQUECERO | L57: Plazo fijo | M57: Ordinaria ART 22 | N57: Extensión de Beneficio Sindicato 1 | O57: mensual | P57: 42.5 | Q57: 46001
A58: 21.042.313-3 | B58: Activo | C58: Gonzalez Muñoz Diego Andres | D58: F-2sep25 | E58: M | F58: 45909 | G58: 37420 | H58: 930232989 | I58: F&B | J58: COCINA | K58: COMMIS | L58: Plazo fijo | M58: Ordinaria ART 22 | N58: Extensión de Beneficio Sindicato 1 | O58: mensual | P58: 42.5 | Q58: 46001
A59: 14.171.763-4 | B59: Activo | C59: Román Ferreira Susana Inés | D59: F-1sep25 | E59: F | F59: 45902 | G59: 29445 | H59: 950516210 | I59: F&B | J59: STEWARD | K59: PLAQUECERO | L59: Plazo fijo | M59: Ordinaria ART 22 | N59: Extensión de Beneficio Sindicato 2 | O59: mensual | P59: 42.5 | Q59: 46008
A60: 25.955.327-k | B60: Activo | C60: Delva - Yol Bine Mose Ricka | D60: F-3ago25 | E60: F | F60: 45890 | G60: 38371 | H60: 949833163 | I60: F&B | J60: STEWARD | K60: PLAQUECERO | L60: Plazo fijo | M60: Ordinaria ART 22 | N60: Extensión de Beneficio Sindicato 1 | O60: mensual | P60: 42.5 | Q60: 45999
A61: 18.637.768-0 | B61: Activo | C61: Bastías González María Jesús | D61: F-2oct25 | E61: F | F61: 45939 | G61: 34178 | H61: 974960934 | I61: F&B | J61: COCINA | K61: COMMIS | L61: Plazo fijo | M61: Ordinaria ART 22 | N61: Extensión de Beneficio Sindicato 1 | O61: mensual | P61: 42.5 | Q61: 45999
A62: 22.207.390-1 | B62: Activo | C62: Garrido Garro Martin Leandro | D62: F-4sep25 | E62: M | F62: 45927 | G62: 38969 | H62: 998954307 | I62: F&B | J62: COCINA | K62: COMMIS | L62: Plazo fijo | M62: Ordinaria ART 22 | N62: Extensión de Beneficio Sindicato 1 | O62: mensual | P62: 42.5 | Q62: 46003
A63: 21.271.915-3 | B63: Activo | C63: Gonzalez Jara Carla Pia | D63: F-4sep25 | E63: F | F63: 45925 | G63: 37705 | H63: 929053336 | I63: F&B | J63: COCINA | K63: COMMIS | L63: Plazo fijo | M63: Ordinaria ART 22 | N63: Extensión de Beneficio Sindicato 1 | O63: mensual | P63: 42.5 | Q63: 46001
...

Sheet NOMINA OCTUBRE
A1: PEGAR REPORTE " DAILY REPORTE DE BUK " DEL MES ANTERIOR A REPORTAR
A2: MOVER LA COLUMNA DE NUMERO DE DOCUMENTO AL INICIO
A3: ELIMINAR COLUMNA SUELDO BASE
A4: ELIMINAR COLUMNA Haberes No Imponibles - Movilización
A5: ELIMINAR COLUMNA CENTRO COSTOS Y ADICIONALES
A7: Asociado - Número de Documento | B7: Asociado - Estado | C7: Asociado - Nombre Completo | D7: Asociado - Código de Ficha | E7: Asociado - Sexo | F7: Trabajo - Fecha Ingreso Compañía | G7: Asociado - Fecha de Nacimiento | H7: Asociado - Teléfono Particular | I7: Trabajo - Nombre Área | J7: Trabajo - Nombre Sub-área Asignada(o) | K7: Trabajo - Cargo | L7: Trabajo - Tipo de Contrato | M7: Trabajo - Tipo de Jornada | N7: Trabajo - Sindicato | O7: Trabajo - Jornada Laboral | P7: Trabajo - Horas Semanales | Q7: Trabajo - Fecha Vencimiento Contrato
A8: 25.724.970-0 | B8: Inactivo | C8: Araujo Moya Naibel Del Valle | D8: F-1jul25 | E8: F | F8: 45839 | G8: 31847 | H8: 971772773 | I8: MEMO | J8: PALAFITO | K8: CHEF ENCARGADO DE PALAFITO | L8: Plazo fijo | M8: Ordinaria ART 22 | N8: Extensión de Beneficio Sindicato 1 | O8: mensual | P8: 42.5 | Q8: 45932
A9: 14.171.763-4 | B9: Activo | C9: Román Ferreira Susana Inés | D9: F-1sep25 | E9: F | F9: 45902 | G9: 29445 | H9: 950516210 | I9: F&B | J9: STEWARD | K9: PLAQUECERO | L9: Plazo fijo | M9: Ordinaria ART 22 | N9: Extensión de Beneficio Sindicato 2 | O9: mensual | P9: 42.5 | Q9: 46008
A10: 16.369.570-7 | B10: Activo | C10: Fuentes Castillo Macarena Alejandra | D10: F1 | E10: F | F10: 45873 | G10: 32003 | H10: 994060922 | I10: F&B | J10: OFICINA DE BANQUETES | K10: COORDINADOR(A) DE BANQUETES | L10: Plazo fijo | M10: Ordinaria ART 22 | N10: Extensión de Beneficio Sindicato 1 | O10: mensual | P10: 42.5 | Q10: 45964
A11: 18.629.669-9 | B11: Inactivo | C11: Hernández Jorquera Pablo Andrés | D11: F-1ago25 | E11: M | F11: 45873 | G11: 34492 | H11: 995130891 | I11: F&B | J11: STEWARD | K11: PLAQUECERO | L11: Plazo fijo | M11: Ordinaria ART 22 | N11: Extensión de Beneficio Sindicato 2 | O11: mensual | P11: 42.5 | Q11: 45947
A12: 23.816.541-5 | B12: Activo | C12: Pecovnik Cortes Igor | D12: F1 | E12: M | F12: 42911 | G12: 26528 | H12: 999368991 | I12: ROOMS | J12: GROOMS | K12: Grooms/Portero/Valet | L12: Indefinido | M12: Ordinaria ART 22 | N12: Sindicato 1 | O12: mensual | P12: 42.5
A13: 21.042.313-3 | B13: Activo | C13: Gonzalez Muñoz Diego Andres | D13: F-2sep25 | E13: M | F13: 45909 | G13: 37420 | H13: 930232989 | I13: F&B | J13: COCINA | K13: COMMIS | L13: Plazo fijo | M13: Ordinaria ART 22 | N13: Extensión de Beneficio Sindicato 1 | O13: mensual | P13: 42.5 | Q13: 46001
A14: 19.894.223-5 | B14: Activo | C14: Faundez Vallejos Ailin Cricel | D14: F1 | E14: F | F14: 45740 | G14: 35733 | H14: 966647464 | I14: ADMINISTRACION Y GERENCIA | J14: SEGURIDAD | K14: GUARDIA | L14: Indefinido | M14: Ordinaria ART 22 | N14: Sindicato 1 | O14: mensual | P14: 44
A15: 21.498.229-3 | B15: Inactivo | C15: Muñoz Iturra Ignacio Antonio | D15: F-1ago25 | E15: M | F15: 45876 | G15: 38018 | H15: 627092500 | I15: F&B | J15: COCINA | K15: COMMIS | L15: Plazo fijo | M15: Ordinaria ART 22 | N15: Extensión de Beneficio Sindicato 1 | O15: mensual | P15: 42.5 | Q15: 45950
A16: 21.559.331-2 | B16: Inactivo | C16: Pinto Herrera Maria Cristina | D16: F-1ago25 | E16: F | F16: 45876 | G16: 38101 | H16: 963867755 | I16: F&B | J16: COCINA | K16: COMMIS | L16: Plazo fijo | M16: Ordinaria ART 22 | N16: Extensión de Beneficio Sindicato 1 | O16: mensual | P16: 42.5 | Q16: 45950
A17: 19.429.624-k | B17: Activo | C17: Pons Valenzuela Fernanda Edith | D17: F1 | E17: F | F17: 45733 | G17: 35314 | H17: 957168583 | I17: F&B | J17: COCINA | K17: COMMIS | L17: Indefinido | M17: Ordinaria ART 22 | N17: Sindicato 1 | O17: mensual | P17: 42.5
A18: 25.399.125-9 | B18: Activo | C18: Seljak Piña Franz Isidro | D18: F1 | E18: F | F18: 45698 | G18: 34083 | H18: 958147239 | I18: F&B | J18: COCINA | K18: CHEF DE PARTIE | L18: Indefinido | M18: Ordinaria ART 22 | N18: Sindicato 1 | O18: mensual | P18: 42.5
A19: 19.837.527-6 | B19: Activo | C19: Troncoso Enriquez Luis David | D19: F1 | E19: M | F19: 45873 | G19: 35732 | H19: 965198972 | I19: ROOMS | J19: GUEST SERVICES AGENT | K19: GUEST SERVICE AGENT | L19: Indefinido | M19: Ordinaria ART 22 | N19: Extensión de Beneficio Sindicato 2 | O19: mensual | P19: 42.5
A20: 18.637.768-0 | B20: Inactivo | C20: Bastías González María Jesús | D20: F2jul25 | E20: F | F20: 45845 | G20: 34178 | H20: 974960934 | I20: F&B | J20: COCINA | K20: COMMIS | L20: Plazo fijo | M20: Ordinaria ART 22 | N20: Extensión de Beneficio Sindicato 1 | O20: mensual | P20: 42.5 | Q20: 45936
A21: 10.234.877-k | B21: Activo | C21: Salas Villaceca David Antonio | D21: F1 | E21: M | F21: 38153 | G21: 23601 | H21: 988189560 | I21: ADMINISTRACION Y GERENCIA | J21: CONTRALORIA | K21: CAJERO CENTRAL/COBRADOR | L21: Indefinido | M21: Exenta ART 22 | N21: Extensión de Beneficio Sindicato 1 | O21: mensual | P21: 42.5
A22: 26.610.495-2 | B22: Activo | C22: Pierre - Esaie | D22: F-1jul25 | E22: M | F22: 45842 | G22: 34217 | H22: 968759462 | I22: F&B | J22: STEWARD | K22: PLAQUECERO | L22: Plazo fijo | M22: Ordinaria ART 22 | N22: Extensión de Beneficio Sindicato 1 | O22: mensual | P22: 42.5 | Q22: 45986
A23: 21.484.420-6 | B23: Inactivo | C23: Huechantes Obando Joshua Del Piero | D23: F-3ago25 | E23: M | F23: 45892 | G23: 37997 | H23: 941175921 | I23: F&B | J23: LOBBY BAR | K23: BARTENDER | L23: Plazo fijo | M23: Ordinaria ART 22 | N23: Extensión de Beneficio Sindicato 1 | O23: mensual | P23: 42.5 | Q23: 45946
A24: 17.924.524-8 | B24: Activo | C24: Marinao Cid Gabriel Isaías | D24: F1 | E24: M | F24: 45810 | G24: 33394 | H24: 926220231 | I24: ADMINISTRACION Y GERENCIA | J24: SEGURIDAD | K24: GUARDIA | L24: Indefinido | M24: Ordinaria ART 22 | N24: Sindicato 1 | O24: mensual | P24: 44
A25: 26.854.920-k | B25: Inactivo | C25: Romelus - Ralph | D25: F-2jul25 | E25: M | F25: 45849 | G25: 23475 | H25: 933593190 | I25: F&B | J25: STEWARD | K25: PLAQUECERO | L25: Plazo fijo | M25: Ordinaria ART 22 | N25: Extensión de Beneficio Sindicato 1 | O25: mensual | P25: 42.5 | Q25: 45938
A26: 21.286.136-7 | B26: Activo | C26: Fieldhouse Reyes Alonso Emilio | D26: F1 | E26: M | F26: 45864 | G26: 37736 | H26: 965773140 | I26: ROOMS | J26: GUEST SERVICES AGENT | K26: GUEST SERVICE AGENT | L26: Indefinido | M26: Ordinaria ART 22 | N26: Sindicato 1 | O26: mensual | P26: 42.5
A27: 26.187.200-5 | B27: Inactivo | C27: Cobo Serna Paula Andrea | D27: F-2sep25 | E27: F | F27: 45908 | G27: 28309 | H27: 979137813 | I27: ROOMS | J27: AMA DE LLAVES | K27: MUCAMA (O) /ASEADOR (A) /LENCERA (O) | L27: Plazo fijo | M27: Ordinaria ART 22 | N27: Extensión de Beneficio Sindicato 2 | O27: mensual | P27: 42.5 | Q27: 45949
A28: 24.753.417-2 | B28: Activo | C28: Velazquez Maria Eugenia | D28: F-3sep25 | E28: F | F28: 45915 | G28: 32347 | H28: 986908175 | I28: MEMO | J28: PALAFITO | K28: AYUDANTE DE COCINA / PLAQUECERO | L28: Plazo fijo | M28: Ordinaria ART 22 | N28: Extensión de Beneficio Sindicato 1 | O28: mensual | P28: 42.5 | Q28: 45973
A29: 20.328.286-9 | B29: Inactivo | C29: Lopez Soto Benjamin Alejandro | D29: F-1sep25 | E29: M | F29: 45901 | G29: 36432 | H29: 948489580 | I29: F&B | J29: STEWARD | K29: PLAQUECERO | L29: Plazo fijo | M29: Ordinaria ART 22 | N29: Extensión de Beneficio Sindicato 1 | O29: mensual | P29: 42.5 | Q29: 45949
A30: 25.519.267-1 | B30: Inactivo | C30: Henry - Bertha | D30: F-2jul25 | E30: F | F30: 45849 | G30: 33365 | H30: 932969731 | I30: F&B | J30: STEWARD | K30: PLAQUECERO | L30: Plazo fijo | M30: Ordinaria ART 22 | N30: Extensión de Beneficio Sindicato 1 | O30: mensual | P30: 42.5 | Q30: 45938
A31: 15.381.940-8 | B31: Activo | C31: Mora Gutierrez Rodrigo Alejandro | D31: F1 | E31: M | F31: 45854 | G31: 30236 | H31: 973379381 | I31: F&B | J31: STEWARD | K31: PLAQUECERO | L31: Indefinido | M31: Ordinaria ART 22 | N31: Sindicato 1 | O31: mensual | P31: 42.5
A32: 9.608.528-1 | B32: Activo | C32: Sepulveda Veloso Javier Antonio | D32: F1 | E32: M | F32: 45356 | G32: 23263 | H32: 997339466 | I32: ADMINISTRACION Y GERENCIA | J32: SEGURIDAD | K32: GUARDIA | L32: Indefinido | M32: Ordinaria ART 22 | N32: Sindicato 1 | O32: mensual | P32: 44
A33: 20.464.927-8 | B33: Inactivo | C33: Rojas Avalos Diego Alonso | D33: F-4jul25 | E33: M | F33: 45861 | G33: 36580 | H33: 965753637 | I33: F&B | J33: CID | K33: GARZON/CAJERO OUTLETS | L33: Plazo fijo | M33: Ordinaria ART 22 | N33: Extensión de Beneficio Sindicato 1 | O33: mensual | P33: 42.5 | Q33: 45945
A34: 21.229.689-9 | B34: Inactivo | C34: Flores Mora Bastián Salomón | D34: F-4ago25 | E34: M | F34: 45887 | G34: 37658 | H34: 947476835 | I34: ROOMS | J34: GROOMS | K34: PORTERO/GROOM | L34: Plazo fijo | M34: Ordinaria ART 22 | N34: Extensión de Beneficio Sindicato 1 | O34: mensual | P34: 42.5 | Q34: 45945
A35: 21.348.035-9 | B35: Inactivo | C35: Venegas Zuñiga Danae Vaitiare | D35: F-1ago25 | E35: F | F35: 45873 | G35: 37823 | H35: 938741771 | I35: MEMO | J35: PALAFITO | K35: PLAQUECERO(A)/COCINERO(A) | L35: Plazo fijo | M35: Ordinaria ART 22 | N35: Extensión de Beneficio Sindicato 2 | O35: mensual | P35: 42.5 | Q35: 45947
A36: 15.663.854-4 | B36: Inactivo | C36: Díaz Pérez Angelina Karina | D36: F-2sep25 | E36: F | F36: 45908 | G36: 30601 | H36: 958084027 | I36: ROOMS | J36: AMA DE LLAVES | K36: MUCAMA (O) /ASEADOR (A) /LENCERA (O) | L36: Plazo fijo | M36: Ordinaria ART 22 | N36: Extensión de Beneficio Sindicato 2 | O36: mensual | P36: 42.5 | Q36: 45936
A37: 21.010.433-k | B37: Inactivo | C37: Valenzuela Morales Catalina Andrea | D37: F-2sep25 | E37: F | F37: 45913 | G37: 37385 | H37: 977292815 | I37: ROOMS | J37: GUEST SERVICES AGENT | K37: GUEST SERVICE AGENT | L37: Plazo fijo | M37: Parcial ART 40 BIS | O37: diaria | P37: 20 | Q37: 45935
A38: 20.986.847-4 | B38: Inactivo | C38: Ponce Vega Matias Andres | D38: F-4jul25 | E38: M | F38: 45868 | G38: 37332 | H38: 930544509 | I38: F&B | J38: CID | K38: GARZON/CAJERO OUTLETS | L38: Plazo fijo | M38: Ordinaria ART 22 | N38: Extensión de Beneficio Sindicato 1 | O38: mensual | P38: 42.5 | Q38: 45947
A39: 24.083.390-5 | B39: Inactivo | C39: Padilla Arancibia Cinthia Marcela | D39: F-2sep25 | E39: F | F39: 45908 | G39: 30815 | H39: 940013897 | I39: MEMO | J39: PALAFITO | K39: COMMIS | L39: Plazo fijo | M39: Ordinaria ART 22 | N39: Extensión de Beneficio Sindicato 2 | O39: mensual | P39: 42.5 | Q39: 45950
A40: 28.643.071-6 | B40: Inactivo | C40: Garrido Colmenares Carlos Henrrique | D40: F-4jul25 | E40: M | F40: 45863 | G40: 29786 | H40: 932388896 | I40: ROOMS | J40: PUBLIC AREAS | K40: ASEADOR (A) /OPERARIO DE LAVANDERIA | L40: Plazo fijo | M40: Ordinaria ART 22 | N40: Extensión de Beneficio Sindicato 2 | O40: mensual | P40: 42.5 | Q40: 45945
A41: 26.008.888-2 | B41: Activo | C41: Ambroise - Faniel | D41: F-1sep25 | E41: M | F41: 45907 | G41: 30407 | H41: 936527566 | I41: F&B | J41: STEWARD | K41: PLAQUECERO | L41: Plazo fijo | M41: Ordinaria ART 22 | N41: Extensión de Beneficio Sindicato 1 | O41: mensual | P41: 42.5 | Q41: 46008
...

Sheet REPORTE FINIQUITO DEL MES A REP
A1: PEGAR REPORTE DE FINIQUITOS DEL MES A ENVIAR
A2: ELIMINAR COLUMNA DE SUELDO LIQUIDO
A4: Asociado - Número de Documento | B4: Asociado - Estado | C4: Asociado - Código de Ficha | D4: Asociado - Nombre Completo | E4: Trabajo - Fecha Ingreso Compañía | F4: Trabajo - Fecha Vencimiento Contrato | G4: Trabajo - Tipo de Contrato | H4: Trabajo - Tipo de Jornada | I4: Trabajo - Jornada Laboral | J4: Asociado - Forma de Pago | K4: Asociado - Banco | L4: Asociado - Tipo de Cuenta | M4: Asociado - Número de Cuenta | N4: Trabajo - Fecha Término Trabajo | O4: Trabajo - Razón de Término | P4: Trabajo - Comentario Interno de Término | Q4: Asociado - Fecha Pago de Finiquito | R4: Campos Personalizados de Asociado - Estado Finiquito | S4: Campos Personalizados de Asociado - Forma Pago Finiquito | T4: Campos Personalizados de Asociado - Fecha de Pago
A5: 25.724.970-0 | B5: Inactivo | C5: F-1jul25 | D5: Araujo Moya Naibel Del Valle | E5: 45839 | F5: 45932 | G5: Plazo fijo | H5: Ordinaria ART 22 | I5: mensual | J5: Transferencia Bancaria | K5: Santander | L5: Corriente | M5: 91530775 | N5: 45932 | O5: vencimiento_plazo | Q5: 45940
A6: 14.171.763-4 | B6: Activo | C6: F-1sep25 | D6: Román Ferreira Susana Inés | E6: 45902 | F6: 46008 | G6: Plazo fijo | H6: Ordinaria ART 22 | I6: mensual | J6: Transferencia Bancaria | K6: Falabella | L6: Corriente | M6: 19822231785
A7: 16.369.570-7 | B7: Activo | C7: F1 | D7: Fuentes Castillo Macarena Alejandra | E7: 45873 | F7: 45964 | G7: Plazo fijo | H7: Ordinaria ART 22 | I7: mensual | J7: Transferencia Bancaria | K7: Falabella | L7: Corriente | M7: 19991394482
A8: 18.629.669-9 | B8: Inactivo | C8: F-1ago25 | D8: Hernández Jorquera Pablo Andrés | E8: 45873 | F8: 45947 | G8: Plazo fijo | H8: Ordinaria ART 22 | I8: mensual | J8: Transferencia Bancaria | K8: Banco Estado | L8: Vista | M8: 18629669 | N8: 45947 | O8: vencimiento_plazo | Q8: 45954
A9: 23.816.541-5 | B9: Activo | C9: F1 | D9: Pecovnik Cortes Igor | E9: 42911 | G9: Indefinido | H9: Ordinaria ART 22 | I9: mensual | J9: Transferencia Bancaria | K9: BCI | L9: Corriente | M9: 53090128
A10: 21.042.313-3 | B10: Activo | C10: F-2sep25 | D10: Gonzalez Muñoz Diego Andres | E10: 45909 | F10: 46001 | G10: Plazo fijo | H10: Ordinaria ART 22 | I10: mensual | J10: Transferencia Bancaria | K10: Banco Estado | L10: Vista | M10: 21042313
A11: 19.894.223-5 | B11: Activo | C11: F1 | D11: Faundez Vallejos Ailin Cricel | E11: 45740 | G11: Indefinido | H11: Ordinaria ART 22 | I11: mensual | J11: Transferencia Bancaria | K11: Falabella | L11: Corriente | M11: 19990463037
A12: 21.498.229-3 | B12: Inactivo | C12: F-1ago25 | D12: Muñoz Iturra Ignacio Antonio | E12: 45876 | F12: 45950 | G12: Plazo fijo | H12: Ordinaria ART 22 | I12: mensual | J12: Transferencia Bancaria | K12: Falabella | L12: Corriente | M12: 19812293715 | N12: 45950 | O12: vencimiento_plazo | Q12: 45954
A13: 21.559.331-2 | B13: Inactivo | C13: F-1ago25 | D13: Pinto Herrera Maria Cristina | E13: 45876 | F13: 45950 | G13: Plazo fijo | H13: Ordinaria ART 22 | I13: mensual | J13: Transferencia Bancaria | K13: Banco Estado | L13: Vista | M13: 21559331 | N13: 45950 | O13: vencimiento_plazo | Q13: 45954
A14: 19.429.624-k | B14: Activo | C14: F1 | D14: Pons Valenzuela Fernanda Edith | E14: 45733 | G14: Indefinido | H14: Ordinaria ART 22 | I14: mensual | J14: Transferencia Bancaria | K14: Falabella | L14: Corriente | M14: 12530148336
A15: 25.399.125-9 | B15: Activo | C15: F1 | D15: Seljak Piña Franz Isidro | E15: 45698 | G15: Indefinido | H15: Ordinaria ART 22 | I15: mensual | J15: Transferencia Bancaria | K15: Santander | L15: Corriente | M15: 72107934
A16: 19.837.527-6 | B16: Activo | C16: F1 | D16: Troncoso Enriquez Luis David | E16: 45873 | G16: Indefinido | H16: Ordinaria ART 22 | I16: mensual | J16: Transferencia Bancaria | K16: Santander | L16: Corriente | M16: 82103651 | S16: Electrónico
A17: 18.637.768-0 | B17: Inactivo | C17: F2jul25 | D17: Bastías González María Jesús | E17: 45845 | F17: 45936 | G17: Plazo fijo | H17: Ordinaria ART 22 | I17: mensual | J17: Transferencia Bancaria | K17: Falabella | L17: Corriente | M17: 15841234260 | N17: 45936 | O17: vencimiento_plazo | Q17: 45940
A18: 10.234.877-k | B18: Activo | C18: F1 | D18: Salas Villaceca David Antonio | E18: 38153 | G18: Indefinido | H18: Exenta ART 22 | I18: mensual | J18: Transferencia Bancaria | K18: Itau | L18: Vista | M18: 202221197
A19: 26.610.495-2 | B19: Activo | C19: F-1jul25 | D19: Pierre - Esaie | E19: 45842 | F19: 45986 | G19: Plazo fijo | H19: Ordinaria ART 22 | I19: mensual | J19: Transferencia Bancaria | K19: Falabella | L19: Corriente | M19: 18800154360
A20: 21.484.420-6 | B20: Inactivo | C20: F-3ago25 | D20: Huechantes Obando Joshua Del Piero | E20: 45892 | F20: 45946 | G20: Plazo fijo | H20: Ordinaria ART 22 | I20: mensual | J20: Transferencia Bancaria | K20: Scotiabank | L20: Corriente | M20: 986723342 | N20: 45946 | O20: vencimiento_plazo | Q20: 45947
A21: 17.924.524-8 | B21: Activo | C21: F1 | D21: Marinao Cid Gabriel Isaías | E21: 45810 | G21: Indefinido | H21: Ordinaria ART 22 | I21: mensual | J21: Transferencia Bancaria | K21: Ripley | L21: Corriente | M21: 4014100038
A22: 26.854.920-k | B22: Inactivo | C22: F-2jul25 | D22: Romelus - Ralph | E22: 45849 | F22: 45938 | G22: Plazo fijo | H22: Ordinaria ART 22 | I22: mensual | J22: Transferencia Bancaria | K22: Banco Estado | L22: Vista | M22: 26854920 | N22: 45938 | O22: vencimiento_plazo | Q22: 45940
A23: 21.286.136-7 | B23: Activo | C23: F1 | D23: Fieldhouse Reyes Alonso Emilio | E23: 45864 | G23: Indefinido | H23: Ordinaria ART 22 | I23: mensual | J23: Transferencia Bancaria | K23: Santander | L23: Corriente | M23: 83844507
A24: 26.187.200-5 | B24: Inactivo | C24: F-2sep25 | D24: Cobo Serna Paula Andrea | E24: 45908 | F24: 45949 | G24: Plazo fijo | H24: Ordinaria ART 22 | I24: mensual | J24: Transferencia Bancaria | K24: Banco Estado | L24: Vista | M24: 26187200 | N24: 45949 | O24: vencimiento_plazo | Q24: 45954
A25: 24.753.417-2 | B25: Activo | C25: F-3sep25 | D25: Velazquez Maria Eugenia | E25: 45915 | F25: 45973 | G25: Plazo fijo | H25: Ordinaria ART 22 | I25: mensual | J25: Transferencia Bancaria | K25: Santander | L25: Ahorro | M25: 80626053
A26: 20.328.286-9 | B26: Inactivo | C26: F-1sep25 | D26: Lopez Soto Benjamin Alejandro | E26: 45901 | F26: 45949 | G26: Plazo fijo | H26: Ordinaria ART 22 | I26: mensual | J26: Transferencia Bancaria | K26: Falabella | L26: Vista | M26: 19801473344 | N26: 45938 | O26: renuncia | Q26: 45940
A27: 25.519.267-1 | B27: Inactivo | C27: F-2jul25 | D27: Henry - Bertha | E27: 45849 | F27: 45938 | G27: Plazo fijo | H27: Ordinaria ART 22 | I27: mensual | J27: Transferencia Bancaria | K27: Banco Estado | L27: Vista | M27: 25519267 | N27: 45938 | O27: vencimiento_plazo | Q27: 45940
A28: 15.381.940-8 | B28: Activo | C28: F1 | D28: Mora Gutierrez Rodrigo Alejandro | E28: 45854 | G28: Indefinido | H28: Ordinaria ART 22 | I28: mensual | J28: Transferencia Bancaria | K28: Banco Estado | L28: Vista | M28: 15381940
A29: 9.608.528-1 | B29: Activo | C29: F1 | D29: Sepulveda Veloso Javier Antonio | E29: 45356 | G29: Indefinido | H29: Ordinaria ART 22 | I29: mensual | J29: Transferencia Bancaria | K29: Banco Estado | L29: Vista | M29: 9608528
A30: 20.464.927-8 | B30: Inactivo | C30: F-4jul25 | D30: Rojas Avalos Diego Alonso | E30: 45861 | F30: 45945 | G30: Plazo fijo | H30: Ordinaria ART 22 | I30: mensual | J30: Transferencia Bancaria | K30: Banco Estado | L30: Vista | M30: 20464927 | N30: 45945 | O30: vencimiento_plazo | Q30: 45947
A31: 21.229.689-9 | B31: Inactivo | C31: F-4ago25 | D31: Flores Mora Bastián Salomón | E31: 45887 | F31: 45945 | G31: Plazo fijo | H31: Ordinaria ART 22 | I31: mensual | J31: Transferencia Bancaria | K31: Santander | L31: Vista | M31: 5621229689 | N31: 45945 | O31: vencimiento_plazo | Q31: 45947
A32: 21.348.035-9 | B32: Inactivo | C32: F-1ago25 | D32: Venegas Zuñiga Danae Vaitiare | E32: 45873 | F32: 45947 | G32: Plazo fijo | H32: Ordinaria ART 22 | I32: mensual | J32: Transferencia Bancaria | K32: Banco Estado | L32: Vista | M32: 21348035 | N32: 45947 | O32: vencimiento_plazo | Q32: 45954
A33: 15.663.854-4 | B33: Inactivo | C33: F-2sep25 | D33: Díaz Pérez Angelina Karina | E33: 45908 | F33: 45936 | G33: Plazo fijo | H33: Ordinaria ART 22 | I33: mensual | J33: Transferencia Bancaria | K33: Banco de Chile | L33: Vista | M33: 1311425251 | N33: 45936 | O33: vencimiento_plazo | Q33: 45940
A34: 21.010.433-k | B34: Inactivo | C34: F-2sep25 | D34: Valenzuela Morales Catalina Andrea | E34: 45913 | F34: 45935 | G34: Plazo fijo | H34: Parcial ART 40 BIS | I34: diaria | J34: Transferencia Bancaria | K34: Scotiabank | L34: Corriente | M34: 310001802862 | N34: 45935 | O34: vencimiento_plazo | Q34: 45940
A35: 20.986.847-4 | B35: Inactivo | C35: F-4jul25 | D35: Ponce Vega Matias Andres | E35: 45868 | F35: 45947 | G35: Plazo fijo | H35: Ordinaria ART 22 | I35: mensual | J35: Transferencia Bancaria | K35: Falabella | L35: Corriente | M35: 17240058243 | N35: 45947 | O35: vencimiento_plazo | Q35: 45954
A36: 24.083.390-5 | B36: Inactivo | C36: F-2sep25 | D36: Padilla Arancibia Cinthia Marcela | E36: 45908 | F36: 45950 | G36: Plazo fijo | H36: Ordinaria ART 22 | I36: mensual | J36: Transferencia Bancaria | K36: Banco Estado | L36: Vista | M36: 24083390 | N36: 45950 | O36: vencimiento_plazo | Q36: 45954
A37: 28.643.071-6 | B37: Inactivo | C37: F-4jul25 | D37: Garrido Colmenares Carlos Henrrique | E37: 45863 | F37: 45945 | G37: Plazo fijo | H37: Ordinaria ART 22 | I37: mensual | J37: Cheque | N37: 45945 | O37: vencimiento_plazo | Q37: 45947
A38: 26.008.888-2 | B38: Activo | C38: F-1sep25 | D38: Ambroise - Faniel | E38: 45907 | F38: 46008 | G38: Plazo fijo | H38: Ordinaria ART 22 | I38: mensual | J38: Transferencia Bancaria | K38: Banco Estado | L38: Vista | M38: 26008888
A39: 12.679.480-0 | B39: Activo | C39: F1 | D39: Rebeco Villablanca Freddy Giovanni | E39: 45873 | G39: Indefinido | H39: Ordinaria ART 22 | I39: mensual | J39: Transferencia Bancaria | K39: Banco Estado | L39: Vista | M39: 12679480
A40: 11.666.268-k | B40: Activo | C40: F1 | D40: Zambrano Mandiola Bernarda Julia | E40: 45821 | G40: Indefinido | H40: Ordinaria ART 22 | I40: mensual | J40: Transferencia Bancaria | K40: Santander | L40: Corriente | M40: 79429856
A41: 26.432.526-9 | B41: Activo | C41: F1 | D41: Shephard Matos Francia Elizabeth | E41: 45815 | G41: Indefinido | H41: Ordinaria ART 22 | I41: mensual | J41: Transferencia Bancaria | K41: Banco Estado | L41: Vista | M41: 26432526
...
